<?xml version="1.0" encoding="UTF-8"?>
<testng-results retried="1" ignored="1" total="6" passed="3" failed="1" skipped="0">
  <reporter-output>
  </reporter-output>
  <suite started-at="2025-05-13T17:56:18 IST" name="Default suite" finished-at="2025-05-13T17:56:49 IST" duration-ms="30440">
    <groups>
    </groups>
    <test started-at="2025-05-13T17:56:18 IST" name="Default test" finished-at="2025-05-13T17:56:49 IST" duration-ms="30440">
      <class name="com.endToEndTesting.orderCompleteTesting">
        <test-method is-config="true" signature="setup()[pri:0, instance:com.endToEndTesting.orderCompleteTesting@44c03695]" started-at="2025-05-13T17:56:19 IST" name="setup" finished-at="2025-05-13T17:56:29 IST" duration-ms="10411" status="PASS">
          <reporter-output>
          </reporter-output>
        </test-method> <!-- setup -->
        <test-method retried="true" signature="testMethod()[pri:0, instance:com.endToEndTesting.orderCompleteTesting@44c03695]" started-at="2025-05-13T17:56:29 IST" name="testMethod" finished-at="2025-05-13T17:56:29 IST" duration-ms="44" status="SKIP">
          <exception class="java.lang.AssertionError">
            <message>
              <![CDATA[expected [false] but found [true]]]>
            </message>
            <full-stacktrace>
              <![CDATA[java.lang.AssertionError: expected [false] but found [true]
at org.testng.Assert.fail(Assert.java:111)
at org.testng.Assert.failNotEquals(Assert.java:1578)
at org.testng.Assert.assertFalse(Assert.java:79)
at org.testng.Assert.assertFalse(Assert.java:89)
at com.endToEndTesting.orderCompleteTesting.testMethod(orderCompleteTesting.java:88)
at java.base/jdk.internal.reflect.DirectMethodHandleAccessor.invoke(DirectMethodHandleAccessor.java:103)
at java.base/java.lang.reflect.Method.invoke(Method.java:580)
at org.testng.internal.invokers.MethodInvocationHelper.invokeMethod(MethodInvocationHelper.java:141)
at org.testng.internal.invokers.TestInvoker.invokeMethod(TestInvoker.java:686)
at org.testng.internal.invokers.TestInvoker.invokeTestMethod(TestInvoker.java:230)
at org.testng.internal.invokers.MethodRunner.runInSequence(MethodRunner.java:63)
at org.testng.internal.invokers.TestInvoker$MethodInvocationAgent.invoke(TestInvoker.java:992)
at org.testng.internal.invokers.TestInvoker.invokeTestMethods(TestInvoker.java:203)
at org.testng.internal.invokers.TestMethodWorker.invokeTestMethods(TestMethodWorker.java:154)
at org.testng.internal.invokers.TestMethodWorker.run(TestMethodWorker.java:134)
at java.base/java.util.ArrayList.forEach(ArrayList.java:1596)
at org.testng.TestRunner.privateRun(TestRunner.java:739)
at org.testng.TestRunner.run(TestRunner.java:614)
at org.testng.SuiteRunner.runTest(SuiteRunner.java:421)
at org.testng.SuiteRunner.runSequentially(SuiteRunner.java:413)
at org.testng.SuiteRunner.privateRun(SuiteRunner.java:373)
at org.testng.SuiteRunner.run(SuiteRunner.java:312)
at org.testng.SuiteRunnerWorker.runSuite(SuiteRunnerWorker.java:52)
at org.testng.SuiteRunnerWorker.run(SuiteRunnerWorker.java:95)
at org.testng.TestNG.runSuitesSequentially(TestNG.java:1274)
at org.testng.TestNG.runSuitesLocally(TestNG.java:1208)
at org.testng.TestNG.runSuites(TestNG.java:1112)
at org.testng.TestNG.run(TestNG.java:1079)
at org.testng.remote.AbstractRemoteTestNG.run(AbstractRemoteTestNG.java:115)
at org.testng.remote.RemoteTestNG.initAndRun(RemoteTestNG.java:293)
at org.testng.remote.RemoteTestNG.main(RemoteTestNG.java:91)
]]>
            </full-stacktrace>
          </exception> <!-- java.lang.AssertionError -->
          <reporter-output>
          </reporter-output>
        </test-method> <!-- testMethod -->
        <test-method signature="testMethod()[pri:0, instance:com.endToEndTesting.orderCompleteTesting@44c03695]" started-at="2025-05-13T17:56:29 IST" name="testMethod" finished-at="2025-05-13T17:56:29 IST" duration-ms="8" status="FAIL">
          <exception class="java.lang.AssertionError">
            <message>
              <![CDATA[expected [false] but found [true]]]>
            </message>
            <full-stacktrace>
              <![CDATA[java.lang.AssertionError: expected [false] but found [true]
at org.testng.Assert.fail(Assert.java:111)
at org.testng.Assert.failNotEquals(Assert.java:1578)
at org.testng.Assert.assertFalse(Assert.java:79)
at org.testng.Assert.assertFalse(Assert.java:89)
at com.endToEndTesting.orderCompleteTesting.testMethod(orderCompleteTesting.java:88)
at java.base/jdk.internal.reflect.DirectMethodHandleAccessor.invoke(DirectMethodHandleAccessor.java:103)
at java.base/java.lang.reflect.Method.invoke(Method.java:580)
at org.testng.internal.invokers.MethodInvocationHelper.invokeMethod(MethodInvocationHelper.java:141)
at org.testng.internal.invokers.TestInvoker.invokeMethod(TestInvoker.java:686)
at org.testng.internal.invokers.TestInvoker.retryFailed(TestInvoker.java:269)
at org.testng.internal.invokers.MethodRunner.runInSequence(MethodRunner.java:76)
at org.testng.internal.invokers.TestInvoker$MethodInvocationAgent.invoke(TestInvoker.java:992)
at org.testng.internal.invokers.TestInvoker.invokeTestMethods(TestInvoker.java:203)
at org.testng.internal.invokers.TestMethodWorker.invokeTestMethods(TestMethodWorker.java:154)
at org.testng.internal.invokers.TestMethodWorker.run(TestMethodWorker.java:134)
at java.base/java.util.ArrayList.forEach(ArrayList.java:1596)
at org.testng.TestRunner.privateRun(TestRunner.java:739)
at org.testng.TestRunner.run(TestRunner.java:614)
at org.testng.SuiteRunner.runTest(SuiteRunner.java:421)
at org.testng.SuiteRunner.runSequentially(SuiteRunner.java:413)
at org.testng.SuiteRunner.privateRun(SuiteRunner.java:373)
at org.testng.SuiteRunner.run(SuiteRunner.java:312)
at org.testng.SuiteRunnerWorker.runSuite(SuiteRunnerWorker.java:52)
at org.testng.SuiteRunnerWorker.run(SuiteRunnerWorker.java:95)
at org.testng.TestNG.runSuitesSequentially(TestNG.java:1274)
at org.testng.TestNG.runSuitesLocally(TestNG.java:1208)
at org.testng.TestNG.runSuites(TestNG.java:1112)
at org.testng.TestNG.run(TestNG.java:1079)
at org.testng.remote.AbstractRemoteTestNG.run(AbstractRemoteTestNG.java:115)
at org.testng.remote.RemoteTestNG.initAndRun(RemoteTestNG.java:293)
at org.testng.remote.RemoteTestNG.main(RemoteTestNG.java:91)
]]>
            </full-stacktrace>
          </exception> <!-- java.lang.AssertionError -->
          <reporter-output>
          </reporter-output>
        </test-method> <!-- testMethod -->
        <test-method signature="SelectProduct()[pri:1, instance:com.endToEndTesting.orderCompleteTesting@44c03695]" started-at="2025-05-13T17:56:29 IST" name="SelectProduct" finished-at="2025-05-13T17:56:35 IST" duration-ms="5091" status="PASS">
          <reporter-output>
          </reporter-output>
        </test-method> <!-- SelectProduct -->
        <test-method signature="selectProductOne()[pri:2, instance:com.endToEndTesting.orderCompleteTesting@44c03695]" started-at="2025-05-13T17:56:35 IST" name="selectProductOne" finished-at="2025-05-13T17:56:40 IST" duration-ms="4952" status="PASS">
          <reporter-output>
          </reporter-output>
        </test-method> <!-- selectProductOne -->
        <test-method signature="CustomerDetails()[pri:3, instance:com.endToEndTesting.orderCompleteTesting@44c03695]" started-at="2025-05-13T17:56:40 IST" name="CustomerDetails" finished-at="2025-05-13T17:56:49 IST" duration-ms="9374" status="PASS">
          <reporter-output>
          </reporter-output>
        </test-method> <!-- CustomerDetails -->
      </class> <!-- com.endToEndTesting.orderCompleteTesting -->
    </test> <!-- Default test -->
  </suite> <!-- Default suite -->
</testng-results>
